Workbook

Sheet 原材料成本计算方法
A1: 需要输入的信息
A3: 产品信息
A4: 长（mm) | B4: 270 | C4: 宽（mm) | D4: 350
A5: 厚度（mm) | B5: 0.06 | C5: 插底（mm) | D5: 20
A6: 长度飞边（mm) | B6: 10 | C6: 拉链条米克重 | D6: 8.5
A7: 包装方式 | B7: 盒装 | C7: 拉链颜色 | D7: 瓷白
A8: 盒入数 | B8: 8 | C8: 箱入数 | D8: 80
A9: 印刷 | B9: 一色 | C9: 可印只/桶 | D9: 160000
A10: 原料配比/份数（袋本体）
A11: LDPE | B11: =1/3 -> 0.33333333 | C11: LLDPE | D11: =2/3 -> 0.66666667
A12: 原料配比/份数（拉链）
A13: 色母 | C13: 0.02
A14: 其他 | C14: LDPE（份数） | D14: 100 | E14: 0.98
C15: LLDPE（份数） | D15: 20
C16: MLLDPE（份数） | D16: 10
C17: HDPE（份数） | D17: 5
A18: 物料价格
A19: LDPE | B19: 13500 | C19: 元/吨
A20: LLDPE | B20: 10500 | C20: 元/吨
A21: MLLDPE | B21: 12500 | C21: 元/吨
A22: HDPE | B22: 11000 | C22: 元/吨
A23: 色母 | B23: 20000 | C23: 元/吨
A24: 水墨 | B24: 45 | C24: 元/千克
A25: 拉链头 | B25: 0.01 | C25: 元/个
A26: 印刷版 | B26: 300 | C26: 元/个
A27: 彩盒 | B27: 0.42 | C27: 元/个
A28: 热熔胶 | B28: 23 | C28: 元/千克
A29: 外箱 | B29: 4.8 | C29: 元/个
A31: 成本计算（每个袋子）
A32: 袋本体混合原料成本 | B32: =(B19*B11+B20*D11) -> 11500 | C32: 元/吨
A33: 拉链条混合原料成本 | B33: =C13*B23+E14*(B19*D14/(D14+D15+D16+D17)+B20*D15/(D14+D15+D16+D17)+B21*D16/(D14+D15+D16+D17)+B22*D17/(D14+D15+D16+D17)) -> 13031.111 | C33: 元/吨
A34: 袋本体重量（成品） | B34: =(B4+D5)*D4*B5*2*0.00092 -> 11.2056 | C34: 袋本体重量计算公式，0.00092为PE的密度
A35: 袋本体重量（吹膜） | B35: =B34*(B6+B4+D15)/(B4+D5) -> 11.592 | C35: 飞边部分也要算入成本中
A36: 袋本体原料成本 | B36: =B32*B35/1000000 -> 0.133308
A37: 水墨成本 | B37: =18*B24/D9 -> 0.0050625 | C37: 没桶18kg
A38: 印刷版成本 | B38: =300/(100000/D4*1000) -> 0.00105 | C38: 每个版能印10万米
A39: 拉链条重量 | B39: =D4/1000*D6 -> 2.975
A40: 拉链条成本 | B40: =B39*B33/1000000 -> 0.038767556
A41: 拉链头成本 | B41: =B25 -> 0.01
A42: 每个袋子摊热熔胶成本 | B42: =0.7*B28/1000/B8 -> 0.0020125 | C42: 热熔胶每盒用量0.7g
...

Sheet Sheet1
B2: 袋本体 | C2: 拉链 | D2: 拉链头 | E2: 印刷 | F2: 打胶 | G2: 盒 | H2: 箱 | I2: 合计
A3: L22 | B3: =原材料成本计算方法!B36 -> 0.133308 | C3: =原材料成本计算方法!B40 -> 0.038767556 | D3: =原材料成本计算方法!B41 -> 0.01 | E3: =原材料成本计算方法!B37+原材料成本计算方法!B38 -> 0.0061125 | F3: =原材料成本计算方法!B42 -> 0.0020125 | G3: =原材料成本计算方法!B44 -> 0.0525 | H3: =原材料成本计算方法!B45 -> 0.0075 | I3: =SUM(B3:H3) -> 0.25020056
